<?xml version="1.0"?>
<robot xmlns:xacro="http://www.ros.org/wiki/xacro">

    <xacro:include filename="inertial_macros.xacro"/>

    <material name="grey">
        <color rgba="0.4196078431372549 0.48627450980392156 0.5215686274509804 1.0"/>
    </material>

    <material name="orange">
        <color rgba="1 0.3 0.1 1"/>
    </material>

    <material name="black">
        <color rgba="0 0 0 1"/>
    </material>

    <material name="white">
        <color rgba="1 1 1 1"/>
    </material>

    <material name="red">
        <color rgba="0.8980392156862745 0.0 0.0 1.0"/>
    </material>

    <material name="gold">
        <color rgba="0.8588235294117647 0.7058823529411765 0.047058823529411764 1.0"/>
    </material>

      <!-- BASE LINK--> 
    <link name="base_link">
        
    </link>

     <!-- BASE_FOOTPRINT LINK -->
    <joint name="base_footprint_joint" type="fixed">
        <parent link="base_link"/>
        <child link="base_footprint"/>
        <origin xyz="0 0 -0.02961" rpy="0 0 0"/>
    </joint>

    <link name="base_footprint">
    </link>

    <!-- CHASSIS LINK-->
    <joint name="Chassis_joint" type="fixed">
        <parent link="base_link"/>
        <child link="chassis"/>
        <origin xyz="-0.02065 0 0.00792"/>
    </joint>

    <link name="chassis">
        <visual>
        <origin xyz="0.078185 0 0.0458"/>
            <geometry>
                <box size="0.15637 0.062 0.060"/>
            </geometry>
            <material name="grey"></material>
        </visual>
        <collision>
        <origin xyz="0.078185 0 0.0458"/>
            <geometry>
                <box size="0.15637 0.062 0.060"/>
            </geometry>
        </collision>
        <xacro:inertial_box mass="0.567" x="0.15637" y="0.062" z="0.060">
            <origin xyz="0.078185 0 0.0458" rpy="0 0 0"/>
        </xacro:inertial_box>
    </link>

    <!-- Left Wheel-->
    <joint name="left_wheel_joint" type="continuous">
        <parent link="base_link"/>
        <child link="left_wheel"/>
        <origin xyz="0 0.051115 0" rpy="-${pi/2} 0 0"/>
        <axis xyz="0.0 0.0 1"/>
    </joint>

    <link name="left_wheel">
        <visual>
            <geometry>
                <cylinder radius="0.0225" length="0.01775"/>
            </geometry>    
            <material name="black"></material>
        </visual>
        <collision>
            <geometry>
                <cylinder radius="0.0225" length="0.01775"/>
            </geometry>    
        </collision>
        <xacro:inertial_cylinder mass="0.01622" length="0.01775" radius="0.0215">
            <origin xyz="0 0 0" rpy="0 0 0"/>
        </xacro:inertial_cylinder>
    </link>

    <!-- Right Wheel-->
    <joint name="right_wheel_joint" type="continuous">
        <parent link="base_link"/>
        <child link="right_wheel"/>
        <origin xyz="0 -0.051115 0" rpy="${pi/2} 0 0"/>
        <axis xyz="0.0 0.0 -1"/>
    </joint>

    <link name="right_wheel">
        <visual>
            <geometry>
                <cylinder radius="0.0225" length="0.01775"/>
            </geometry>    
            <material name="black"></material>
        </visual>
        <collision>
            <geometry>
                <cylinder radius="0.0225" length="0.01775"/>
            </geometry>    
        </collision>
        <xacro:inertial_cylinder mass="0.01622" length="0.01775" radius="0.0215">
            <origin xyz="0 0 0" rpy="0 0 0"/>
        </xacro:inertial_cylinder>
    </link>

    <!-- Caster Wheel-->
    <joint name="caster_wheel_joint" type="fixed">
        <parent link="chassis"/>
        <child link="caster_wheel"/>
        <origin xyz="0.13737 0 0"/>
    </joint>

    <link name="caster_wheel">
        <visual>
                <geometry>
                    <sphere radius="0.03054"/>
                </geometry>   
            <material name="white"></material>
        </visual>
        <collision>
                <geometry>
                    <sphere radius="0.03054"/>
                </geometry>   
        </collision>
        <xacro:inertial_sphere mass="0.01" radius="0.03054">
            <origin xyz="0 0 0" rpy="0 0 0"/>
        </xacro:inertial_sphere >
    </link>
    
</robot>